<?xml version="1.0" ?>
<robot name="graspe" xmlns:xacro="http://www.ros.org/wiki/xacro">

<!-- include -->
<xacro:include filename="$(find graspe_description)/urdf/materials.xacro" />
<xacro:include filename="$(find graspe_description)/urdf/graspe.trans" />
<xacro:include filename="$(find graspe_description)/urdf/graspe.gazebo" />
<xacro:include filename="$(find graspe_description)/urdf/graspe_joints_limits.xacro" />
<xacro:include filename="$(find graspe_description)/urdf/graspe_gazebo_control.xacro" />

<link name="base_link">
  <inertial>
    <origin xyz="0 0 0" rpy="0 0 0"/>
    <mass value="1.5"/>
    <inertia ixx="0.002199" iyy="0.003694" izz="0.003711" ixy="7e-06" iyz="0.000147" ixz="-1.3e-05"/>
  </inertial>
  <visual>
    <origin xyz="0 0 0" rpy="0 0 0"/>
    <geometry>
      <mesh filename="file://$(find graspe_description)/meshes/base_link.stl" scale="0.001 0.001 0.001"/>
    </geometry>
    <material name="silver"/>
  </visual>
  <collision>
    <origin xyz="0 0 0" rpy="0 0 0"/>
    <geometry>
      <mesh filename="file://$(find graspe_description)/meshes/base_link.stl" scale="0.001 0.001 0.001"/>
    </geometry>
  </collision>
</link>

<!-- first joint (theta1) -->
<link name="rot1_link">
  <inertial>
    <origin xyz="0 0 0" rpy="0 0 0"/>
    <mass value="1.5"/>
    <inertia ixx="0.002199" iyy="0.003694" izz="0.003711" ixy="7e-06" iyz="0.000147" ixz="-1.3e-05"/>
  </inertial>
  <visual>
    <origin xyz="0 0 0" rpy="0 0 0"/>
    <geometry>
      <mesh filename="file://$(find graspe_description)/meshes/rot1.stl" scale="0.001 0.001 0.001"/>
    </geometry>
    <material name="silver"/>
  </visual>
  <collision>
    <origin xyz="0 0 0" rpy="0 0 0"/>
    <geometry>
      <mesh filename="file://$(find graspe_description)/meshes/rot1.stl" scale="0.001 0.001 0.001"/>
    </geometry>
  </collision>
</link>

<joint name="theta1" type="revolute">
  <origin xyz="0.0 0.0 0.08" rpy="0.0 0.0 0.0"/>
  <parent link="base_link"/>
  <child link="rot1_link"/>
  <axis xyz="0.0 0.0 1.0"/>
  <limit lower="${theta1_min}" upper="${theta1_max}" effort="${effort_max}" velocity="${velocity_max}"/>
</joint>

<!-- second joint (theta2) -->
<link name="rot2_link">
  <inertial>
    <origin xyz="0 0 0" rpy="0 0 1.5707"/>
    <mass value="1.5"/>
    <inertia ixx="0.002199" iyy="0.003694" izz="0.003711" ixy="7e-06" iyz="0.000147" ixz="-1.3e-05"/>
  </inertial>
  <visual>
    <origin xyz="0 0 0" rpy="0 0 1.5707"/>
    <geometry>
      <mesh filename="file://$(find graspe_description)/meshes/rot2.stl" scale="0.001 0.001 0.001"/>
    </geometry>
    <material name="silver"/>
  </visual>
  <collision>
    <origin xyz="0 0 0" rpy="0 0 1.5707"/>
    <geometry>
      <mesh filename="file://$(find graspe_description)/meshes/rot2.stl" scale="0.001 0.001 0.001"/>
    </geometry>
  </collision>
</link>

<joint name="theta2" type="revolute">
  <origin xyz="0.0 0.0 0.119" rpy="0.0 0.0 0.0"/>
  <parent link="rot1_link"/>
  <child link="rot2_link"/>
  <axis xyz="0.0 1.0 0.0"/>
  <limit lower="${theta2_min}" upper="${theta2_max}" effort="${effort_max}" velocity="${velocity_max}"/>
</joint>

<!-- prismatic joint (d3) -->
<link name="prismatic3_link">
  <inertial>
    <origin xyz="0 0 0" rpy="0 0 3.1415"/>
    <mass value="1.5"/>
    <inertia ixx="0.002199" iyy="0.003694" izz="0.003711" ixy="7e-06" iyz="0.000147" ixz="-1.3e-05"/>
  </inertial>
  <visual>
    <origin xyz="0 0 0" rpy="0 0 3.1415"/>
    <geometry>
      <mesh filename="file://$(find graspe_description)/meshes/prismatic3.stl" scale="0.001 0.001 0.001"/>
    </geometry>
    <material name="silver"/>
  </visual>
  <collision>
    <origin xyz="0 0 0" rpy="0 0 3.1415"/>
    <geometry>
      <mesh filename="file://$(find graspe_description)/meshes/prismatic3.stl" scale="0.001 0.001 0.001"/>
    </geometry>
  </collision>
</link>

<joint name="d3" type="prismatic">
  <origin xyz="-0.023 0.0 0.008" rpy="0.0 0.0 0.0"/>
  <parent link="rot2_link"/>
  <child link="prismatic3_link"/>
  <axis xyz="0.0 0.0 1.0"/>
  <limit lower="${d3_min}" upper="${d3_max}" effort="${effort_max}" velocity="${velocity_max}"/>
</joint>

<!-- End effector (theta4) -->
<link name="rot4_link">
  <inertial>
    <origin xyz="0 0 0" rpy="0 1.5707 3.1415"/>
    <mass value="1.5"/>
    <inertia ixx="0.002199" iyy="0.003694" izz="0.003711" ixy="7e-06" iyz="0.000147" ixz="-1.3e-05"/>
  </inertial>
  <visual>
    <origin xyz="0 0 0" rpy="0 1.5707 3.1415"/>
    <geometry>
      <mesh filename="file://$(find graspe_description)/meshes/rot4.stl" scale="0.001 0.001 0.001"/>
    </geometry>
    <material name="silver"/>
  </visual>
  <collision>
    <origin xyz="0 0 0" rpy="0 1.5707 3.1415"/>
    <geometry>
      <mesh filename="file://$(find graspe_description)/meshes/rot4.stl" scale="0.001 0.001 0.001"/>
    </geometry>
  </collision>
</link>

<joint name="theta4" type="revolute">
  <origin xyz="0.0195 -0.015 0.1605" rpy="1.5707 0.0 0.0"/>
  <parent link="prismatic3_link"/>
  <child link="rot4_link"/>
  <axis xyz="0.0 0.0 1.0"/>
  <limit lower="${theta4_min}" upper="${theta4_max}" effort="${effort_max}" velocity="${velocity_max}"/>
</joint>

<!-- end effector (scissor) -->
<link name="rot5_link">
  <inertial>
    <origin xyz="0 0 0.006" rpy="0 0 -3.1415"/>
    <mass value="1.5"/>
    <inertia ixx="0.002199" iyy="0.003694" izz="0.003711" ixy="7e-06" iyz="0.000147" ixz="-1.3e-05"/>
  </inertial>
  <visual>
    <origin xyz="0 0 0.006" rpy="0 0 -3.1415"/>
    <geometry>
      <mesh filename="file://$(find graspe_description)/meshes/rot5.stl" scale="0.001 0.001 0.001"/>
    </geometry>
    <material name="silver"/>
  </visual>
  <collision>
    <origin xyz="0 0 0.006" rpy="0 0 -3.1415"/>
    <geometry>
      <mesh filename="file://$(find graspe_description)/meshes/rot5.stl" scale="0.001 0.001 0.001"/>
    </geometry>
  </collision>
</link>

<joint name="scissor" type="revolute">
  <origin xyz="0.0 0.06715 -0.02" rpy="0.0 -1.5707 0.0"/>
  <parent link="rot4_link"/>
  <child link="rot5_link"/>
  <axis xyz="0.0 0.0 1.0"/>
  <limit lower="${scissor_min}" upper="${scissor_max}" effort="${effort_max}" velocity="${velocity_max}"/>
</joint>

</robot>